Workbook
Name Slicer_course_name: #N/A
Name Slicer_enquiry_status: #N/A
Name Slicer_Enquiry_Year: #N/A

Sheet Enquiry_Dashboard
A1: INSTITUTE ENQUIRY & CONVERSION ANALYTICS DASHBOARD
A3: Total Enquiries | E3: Converted Enquiries | I3: Conversion Rate | M3: Lost Enquiries
A4: =Pivot_Analysis!B19 -> 503 | E4: =Pivot_Analysis!AB19 -> 173 | I4: =IFERROR(E4/A4,0) -> 0.34393638 | M4: =GETPIVOTDATA("enquiry_id",Pivot_Analysis!$I$3,"enquiry_status","Lost") -> 30
A49: Note: This dashboard uses synthetic/demo data created for portfolio and analytical purposes.

Sheet Enquiry_Analysis
A1: INSTITUTE ENQUIRY ANALYSIS SUMMARY
A3: Total Enquiries | B3: =COUNTA(Enquiry_Data!A:A)-1 -> 503
A4: Converted Enquiries | B4: =COUNTIF(Enquiry_Data!R:R,"Converted") -> 173
A5: Conversion Rate | B5: =B4/B3 -> 0.34393638
A6: New Enquiries | B6: =COUNTIF(Enquiry_Data!R:R,"New") -> 60
A7: Interested Enquiries | B7: =COUNTIF(Enquiry_Data!R:R,"Interested") -> 90
A8: Follow-up Enquiries | B8: =COUNTIF(Enquiry_Data!R:R,"Follow-up") -> 80
A9: Contacted Enquiries | B9: =COUNTIF(Enquiry_Data!R:R,"Contacted") -> 70
A10: Lost Enquiries | B10: =COUNTIF(Enquiry_Data!R:R,"Lost") -> 30
A11: Live Enquiries | B11: =COUNTIF(Enquiry_Data!T:T,"Live") -> 3
A12: Synthetic Enquiries | B12: =COUNTIF(Enquiry_Data!T:T,"Synthetic") -> 500

Sheet Enquiry_Data
A1: enquiry_id | B1: enquiry_date | C1: Enquiry_Month | D1: Enquiry_Year | E1: Enquiry_Month_No | F1: student_name | G1: email | H1: phone | I1: city | J1: qualification | K1: age_group | L1: course_id | M1: course_name | N1: category | O1: learning_mode | P1: preferred_batch | Q1: lead_source | R1: enquiry_status | S1: Converted_Flag | T1: data_source
A2: 429 | B2: 45658.447 | C2: =TEXT(enquiry_analysis_data[[#This Row],[enquiry_date]],"mmmm-yyyy") -> January-2025 | D2: =YEAR(enquiry_analysis_data[[#This Row],[enquiry_date]]) -> 2025 | E2: =MONTH(enquiry_analysis_data[[#This Row],[enquiry_date]]) -> 1 | F2: Sahil Gupta | G2: demo.student426.sahilgupta@example.com | H2: 9000000426 | I2: Noida | J2: Graduate | K2: 18-21 | L2: CRS001 | M2: Data Analytics | N2: Data & Analytics | O2: Online | P2: Evening | Q2: Instagram | R2: Contacted | S2: =IF(enquiry_analysis_data[[#This Row],[enquiry_status]]="Converted",1,0) -> 0 | T2: Synthetic
A3: 456 | B3: 45658.527 | C3: =TEXT(enquiry_analysis_data[[#This Row],[enquiry_date]],"mmmm-yyyy") -> January-2025 | D3: =YEAR(enquiry_analysis_data[[#This Row],[enquiry_date]]) -> 2025 | E3: =MONTH(enquiry_analysis_data[[#This Row],[enquiry_date]]) -> 1 | F3: Rahul Malik | G3: demo.student453.rahulmalik@example.com | H3: 9000000453 | I3: Delhi | J3: Post Graduate | K3: 22-25 | L3: CRS007 | M3: Digital Marketing | N3: Digital Marketing | O3: Online | P3: Afternoon | Q3: Other | R3: Contacted | S3: =IF(enquiry_analysis_data[[#This Row],[enquiry_status]]="Converted",1,0) -> 0 | T3: Synthetic
A4: 175 | B4: 45661.073 | C4: =TEXT(enquiry_analysis_data[[#This Row],[enquiry_date]],"mmmm-yyyy") -> January-2025 | D4: =YEAR(enquiry_analysis_data[[#This Row],[enquiry_date]]) -> 2025 | E4: =MONTH(enquiry_analysis_data[[#This Row],[enquiry_date]]) -> 1 | F4: Rohit Dahiya | G4: demo.student172.rohitdahiya@example.com | H4: 9000000172 | I4: Delhi | J4: Graduate | K4: 18-21 | L4: CRS004 | M4: AI & Machine Learning | N4: AI & Machine Learning | O4: Offline | P4: Weekend | Q4: LinkedIn | R4: Follow-up | S4: =IF(enquiry_analysis_data[[#This Row],[enquiry_status]]="Converted",1,0) -> 0 | T4: Synthetic
A5: 202 | B5: 45662.41 | C5: =TEXT(enquiry_analysis_data[[#This Row],[enquiry_date]],"mmmm-yyyy") -> January-2025 | D5: =YEAR(enquiry_analysis_data[[#This Row],[enquiry_date]]) -> 2025 | E5: =MONTH(enquiry_analysis_data[[#This Row],[enquiry_date]]) -> 1 | F5: Riya Yadav | G5: demo.student199.riyayadav@example.com | H5: 9000000199 | I5: Gurugram | J5: 12th | K5: 18-21 | L5: CRS002 | M5: Data Science | N5: Data & Analytics | O5: Offline | P5: Morning | Q5: Google Search | R5: Follow-up | S5: =IF(enquiry_analysis_data[[#This Row],[enquiry_status]]="Converted",1,0) -> 0 | T5: Synthetic
A6: 165 | B6: 45663.68 | C6: =TEXT(enquiry_analysis_data[[#This Row],[enquiry_date]],"mmmm-yyyy") -> January-2025 | D6: =YEAR(enquiry_analysis_data[[#This Row],[enquiry_date]]) -> 2025 | E6: =MONTH(enquiry_analysis_data[[#This Row],[enquiry_date]]) -> 1 | F6: Diya Malik | G6: demo.student162.diyamalik@example.com | H6: 9000000162 | I6: Gurugram | J6: 12th | K6: 18-21 | L6: CRS004 | M6: AI & Machine Learning | N6: AI & Machine Learning | O6: Offline | P6: Evening | Q6: Other | R6: Interested | S6: =IF(enquiry_analysis_data[[#This Row],[enquiry_status]]="Converted",1,0) -> 0 | T6: Synthetic
A7: 62 | B7: 45664.665 | C7: =TEXT(enquiry_analysis_data[[#This Row],[enquiry_date]],"mmmm-yyyy") -> January-2025 | D7: =YEAR(enquiry_analysis_data[[#This Row],[enquiry_date]]) -> 2025 | E7: =MONTH(enquiry_analysis_data[[#This Row],[enquiry_date]]) -> 1 | F7: Aditi Chauhan | G7: demo.student059.aditichauhan@example.com | H7: 9000000059 | I7: Ghaziabad | J7: Post Graduate | K7: 22-25 | L7: CRS005 | M7: Full Stack Development | N7: Web Development | O7: Online | P7: Weekend | Q7: Walk-in | R7: Contacted | S7: =IF(enquiry_analysis_data[[#This Row],[enquiry_status]]="Converted",1,0) -> 0 | T7: Synthetic
A8: 500 | B8: 45667.15 | C8: =TEXT(enquiry_analysis_data[[#This Row],[enquiry_date]],"mmmm-yyyy") -> January-2025 | D8: =YEAR(enquiry_analysis_data[[#This Row],[enquiry_date]]) -> 2025 | E8: =MONTH(enquiry_analysis_data[[#This Row],[enquiry_date]]) -> 1 | F8: Prachi Dahiya | G8: demo.student497.prachidahiya@example.com | H8: 9000000497 | I8: Rohtak | J8: Post Graduate | K8: 26-30 | L8: CRS004 | M8: AI & Machine Learning | N8: AI & Machine Learning | O8: Offline | P8: Morning | Q8: Instagram | R8: Converted | S8: =IF(enquiry_analysis_data[[#This Row],[enquiry_status]]="Converted",1,0) -> 1 | T8: Synthetic
A9: 461 | B9: 45667.256 | C9: =TEXT(enquiry_analysis_data[[#This Row],[enquiry_date]],"mmmm-yyyy") -> January-2025 | D9: =YEAR(enquiry_analysis_data[[#This Row],[enquiry_date]]) -> 2025 | E9: =MONTH(enquiry_analysis_data[[#This Row],[enquiry_date]]) -> 1 | F9: Manish Mehta | G9: demo.student458.manishmehta@example.com | H9: 9000000458 | I9: Karnal | J9: 12th | K9: 22-25 | L9: CRS010 | M9: Tally with GST | N9: Accounting | O9: Online | P9: Evening | Q9: LinkedIn | R9: Converted | S9: =IF(enquiry_analysis_data[[#This Row],[enquiry_status]]="Converted",1,0) -> 1 | T9: Synthetic
A10: 75 | B10: 45669.917 | C10: =TEXT(enquiry_analysis_data[[#This Row],[enquiry_date]],"mmmm-yyyy") -> January-2025 | D10: =YEAR(enquiry_analysis_data[[#This Row],[enquiry_date]]) -> 2025 | E10: =MONTH(enquiry_analysis_data[[#This Row],[enquiry_date]]) -> 1 | F10: Deepak Bansal | G10: demo.student072.deepakbansal@example.com | H10: 9000000072 | I10: Faridabad | J10: Post Graduate | K10: 26-30 | L10: CRS003 | M10: Python Programming | N10: Programming | O10: Online | P10: Evening | Q10: Google Search | R10: Converted | S10: =IF(enquiry_analysis_data[[#This Row],[enquiry_status]]="Converted",1,0) -> 1 | T10: Synthetic
A11: 10 | B11: 45677.347 | C11: =TEXT(enquiry_analysis_data[[#This Row],[enquiry_date]],"mmmm-yyyy") -> January-2025 | D11: =YEAR(enquiry_analysis_data[[#This Row],[enquiry_date]]) -> 2025 | E11: =MONTH(enquiry_analysis_data[[#This Row],[enquiry_date]]) -> 1 | F11: Nikhil Kumar | G11: demo.student007.nikhilkumar@example.com | H11: 9000000007 | I11: Delhi | J11: Graduate | K11: 26-30 | L11: CRS003 | M11: Python Programming | N11: Programming | O11: Offline | P11: Morning | Q11: Facebook | R11: Converted | S11: =IF(enquiry_analysis_data[[#This Row],[enquiry_status]]="Converted",1,0) -> 1 | T11: Synthetic
A12: 363 | B12: 45677.565 | C12: =TEXT(enquiry_analysis_data[[#This Row],[enquiry_date]],"mmmm-yyyy") -> January-2025 | D12: =YEAR(enquiry_analysis_data[[#This Row],[enquiry_date]]) -> 2025 | E12: =MONTH(enquiry_analysis_data[[#This Row],[enquiry_date]]) -> 1 | F12: Riya Gupta | G12: demo.student360.riyagupta@example.com | H12: 9000000360 | I12: Noida | J12: Post Graduate | K12: 22-25 | L12: CRS005 | M12: Full Stack Development | N12: Web Development | O12: Offline | P12: Weekend | Q12: Facebook | R12: Interested | S12: =IF(enquiry_analysis_data[[#This Row],[enquiry_status]]="Converted",1,0) -> 0 | T12: Synthetic
A13: 43 | B13: 45678.465 | C13: =TEXT(enquiry_analysis_data[[#This Row],[enquiry_date]],"mmmm-yyyy") -> January-2025 | D13: =YEAR(enquiry_analysis_data[[#This Row],[enquiry_date]]) -> 2025 | E13: =MONTH(enquiry_analysis_data[[#This Row],[enquiry_date]]) -> 1 | F13: Saksham Mehta | G13: demo.student040.sakshammehta@example.com | H13: 9000000040 | I13: Sonipat | J13: 12th | K13: 18-21 | L13: CRS005 | M13: Full Stack Development | N13: Web Development | O13: Online | P13: Evening | Q13: LinkedIn | R13: Follow-up | S13: =IF(enquiry_analysis_data[[#This Row],[enquiry_status]]="Converted",1,0) -> 0 | T13: Synthetic
... A504: 3 | B504: 46288.628 | C504: =TEXT(enquiry_analysis_data[[#This Row],[enquiry_date]],"mmmm-yyyy") -> September-2026 | D504: =YEAR(enquiry_analysis_data[[#This Row],[enquiry_date]]) -> 2026 | E504: =MONTH(enquiry_analysis_data[[#This Row],[enquiry_date]]) -> 9 | F504: VISHANT | G504: VISHUPANCHAL418@GMAIL.COM | H504: 8529637410 | I504: Panipat | J504: Diploma | K504: 18-21 | L504: CRS004 | M504: AI & Machine Learning | N504: AI & Machine Learning | O504: Online | P504: Evening | Q504: Referral | R504: Converted | S504: =IF(enquiry_analysis_data[[#This Row],[enquiry_status]]="Converted",1,0) -> 1 | T504: Live

Sheet Pivot_Analysis
A1: ENQUIRY PIVOT ANALYSIS & VISUALIZATIONS
A3: Course Name | B3: Total Enquiries | E3: Learning Mode | F3: Total Enquiries | I3: Enquiry Status | J3: Total Enquiries | N3: Lead Source | O3: Total Enquiries | R3: Enquiry_Year | S3: Total Enquiries | U3: City | V3: Total Enquiries | Z3: Course Name | AA3: Total Enquiries | AB3: Converted Enquiries | AD3: Qualification | AE3: Total Enquiries
A4: Computer Typing | B4: 50 | E4: Offline | F4: 324 | I4: Contacted | J4: 70 | N4: Google Search | O4: 121 | R4: 2025 | S4: 275 | U4: Karnal | V4: 61 | Z4: Advanced Excel | AA4: 25 | AB4: 7 | AD4: Graduate | AE4: 200
A5: Python Programming | B5: 42 | E5: Online | F5: 179 | I5: Converted | J5: 173 | N5: Instagram | O5: 116 | R5: 1 | S5: 20 | U5: Sonipat | V5: 60 | Z5: AI & Machine Learning | AA5: 25 | AB5: 9 | AD5: 12th | AE5: 110
A6: Video Editing | B6: 40 | E6: Grand Total | F6: 503 | I6: Follow-up | J6: 80 | N6: Referral | O6: 73 | R6: January-2025 | S6: 20 | U6: Noida | V6: 54 | Z6: Basic Computer Course | AA6: 33 | AB6: 10 | AD6: Diploma | AE6: 91
A7: Data Analytics | B7: 39 | I7: Interested | J7: 90 | N7: Walk-in | O7: 56 | R7: 2 | S7: 17 | U7: Faridabad | V7: 54 | Z7: Computer Typing | AA7: 50 | AB7: 19 | AD7: Post Graduate | AE7: 71
A8: Web Designing | B8: 39 | I8: Lost | J8: 30 | N8: Facebook | O8: 45 | R8: February-2025 | S8: 17 | U8: Panipat | V8: 52 | Z8: Data Analytics | AA8: 39 | AB8: 14 | AD8: 10th | AE8: 24
A9: Trading & Financial Market Basics | B9: 36 | I9: New | J9: 60 | N9: YouTube | O9: 40 | R9: 3 | S9: 26 | U9: Bahadurgarh | V9: 49 | Z9: Data Science | AA9: 26 | AB9: 11 | AD9: Other | AE9: 7
A10: Tally with GST | B10: 33 | I10: Grand Total | J10: 503 | N10: LinkedIn | O10: 28 | R10: March-2025 | S10: 26 | U10: Delhi | V10: 46 | Z10: DCA | AA10: 31 | AB10: 7 | AD10: Grand Total | AE10: 503
A11: Basic Computer Course | B11: 33 | N11: Other | O11: 24 | R11: 4 | S11: 22 | U11: Gurugram | V11: 46 | Z11: Digital Marketing | AA11: 25 | AB11: 9
A12: Full Stack Development | B12: 31 | N12: Grand Total | O12: 503 | R12: April-2025 | S12: 22 | U12: Ghaziabad | V12: 43 | Z12: Full Stack Development | AA12: 31 | AB12: 8
A13: DCA | B13: 31 | R13: 5 | S13: 29 | U13: Rohtak | V13: 37 | Z13: Graphic Designing | AA13: 28 | AB13: 10
A14: Graphic Designing | B14: 28 | R14: May-2025 | S14: 29 | U14: Sonepat | V14: 1 | Z14: Python Programming | AA14: 42 | AB14: 15
A15: Data Science | B15: 26 | R15: 6 | S15: 25 | U15: Grand Total | V15: 503 | Z15: Tally with GST | AA15: 33 | AB15: 5
A16: AI & Machine Learning | B16: 25 | R16: June-2025 | S16: 25 | Z16: Trading & Financial Market Basics | AA16: 36 | AB16: 17
A17: Advanced Excel | B17: 25 | R17: 7 | S17: 24 | Z17: Video Editing | AA17: 40 | AB17: 15
A18: Digital Marketing | B18: 25 | R18: July-2025 | S18: 24 | Z18: Web Designing | AA18: 39 | AB18: 17
A19: Grand Total | B19: 503 | R19: 8 | S19: 19 | Z19: Grand Total | AA19: 503 | AB19: 173
E20: Course Category | F20: Total Enquiries | R20: August-2025 | S20: 19
E21: Accounting | F21: 33 | R21: 9 | S21: 23
E22: AI & Machine Learning | F22: 25 | R22: September-2025 | S22: 23 | Z22: Age Group | AA22: Total Enquiries
E23: Computer Applications | F23: 31 | R23: 10 | S23: 30 | Z23: 22-25 | AA23: 164
E24: Computer Basics | F24: 83 | R24: October-2025 | S24: 30 | Z24: 18-21 | AA24: 154 | AD24: Preferred Batch | AE24: Total Enquiries
E25: Creative | F25: 68 | R25: 11 | S25: 15 | Z25: 26-30 | AA25: 94 | AD25: Afternoon | AE25: 112
E26: Data & Analytics | F26: 65 | R26: November-2025 | S26: 15 | Z26: 31+ | AA26: 53 | AD26: Evening | AE26: 128
E27: Digital Marketing | F27: 25 | R27: 12 | S27: 25 | Z27: Below 18 | AA27: 38 | AD27: Morning | AE27: 136
E28: Finance | F28: 36 | R28: December-2025 | S28: 25 | Z28: Grand Total | AA28: 503 | AD28: Weekend | AE28: 127
E29: Office & Analytics | F29: 25 | R29: 2026 | S29: 228 | AD29: Grand Total | AE29: 503
E30: Programming | F30: 42 | R30: 1 | S30: 25
E31: Web Development | F31: 70 | R31: January-2026 | S31: 25
E32: Grand Total | F32: 503 | R32: 2 | S32: 27
R33: February-2026 | S33: 27
R34: 3 | S34: 22
R35: March-2026 | S35: 22
R36: 4 | S36: 22
R37: April-2026 | S37: 22
R38: 5 | S38: 31
R39: May-2026 | S39: 31
R40: 6 | S40: 27
R41: June-2026 | S41: 27
...

Sheet Conversion_Analysis
A2: Course Name | B2: Total Enquiries | C2: Converted Enquiries | D2: Conversion Rate
A3: Advanced Excel | B3: 25 | C3: 7 | D3: 0.28
A4: AI & Machine Learning | B4: 25 | C4: 9 | D4: 0.36
A5: Basic Computer Course | B5: 33 | C5: 10 | D5: 0.3030303
A6: Computer Typing | B6: 50 | C6: 19 | D6: 0.38
A7: Data Analytics | B7: 39 | C7: 14 | D7: 0.35897436
A8: Data Science | B8: 26 | C8: 11 | D8: 0.42307692
A9: DCA | B9: 31 | C9: 7 | D9: 0.22580645
A10: Digital Marketing | B10: 25 | C10: 9 | D10: 0.36
A11: Full Stack Development | B11: 31 | C11: 8 | D11: 0.25806452
A12: Graphic Designing | B12: 28 | C12: 10 | D12: 0.35714286
A13: Python Programming | B13: 42 | C13: 15 | D13: 0.35714286
A14: Tally with GST | B14: 33 | C14: 5 | D14: 0.15151515
... A18: Grand Total | B18: 503 | C18: 173 | D18: 0.34393638
